Workbook
Name Company_name: [1]Assumptions!$F$7
Name Country: [1]Assumptions!$I$22
Name Currency: [1]Assumptions!$I$15
Name Diluted_Shares_Outstanding: [1]DCF!$D$10
Name EBITDA_Multiple: [1]Assumptions!$AM$62
Name Enterprise_Value: [1]DCF!$D$17
Name Equity_Value: [1]DCF!$D$11
Name Hist_Year: [1]Assumptions!$I$26
Name Share_price: [1]Assumptions!$I$19
Name tax_rate: [1]Assumptions!$I$41
Name Terminal_growth_rate: [1]Assumptions!$AF$62
Name Ticker_Name: [1]Assumptions!$F$8
Name Unit_Text: [1]Assumptions!$I$16
Name Val_date: [1]Assumptions!$I$20
Name WACC: [1]DCF!$D$53

Sheet Cover
B7: Company: | D7: Wheel India Limited
B8: Date of Valuation | D8: 46169
B9: Sector: | D9: Auto Components
B11: Current Share price | D11: 1575.8 | E11: INR
B14: INDEX
B15: 1 | C15: Valuation Summary
B16: =B15+1 -> 2 | C16: Assumptions
B17: =B16+1 -> 3 | C17: Scenario Assumptions
B18: =B17+1 -> 4 | C18: Assets Schedule
B19: =B18+1 -> 5 | C19: Debt Schedule
B20: =B19+1 -> 6 | C20: Income Statement
B21: =B20+1 -> 7 | C21: Balance Sheet
B22: =B21+1 -> 8 | C22: Cash Flow Statement
B23: =B22+1 -> 9 | C23: Valuation
B24: =B23+1 -> 10 | C24: Ratios
B25: 11 | C25: Beta Calculation

Sheet Valuation Summary
B3: Metric | C3: BEAR SCENARIO | D3: Base Scenario | E3: BULL SCENARIO
B5: WACC | C5: 0.145 | D5: =Valuation!D14 -> 0.14134765 | E5: 0.137
B6: Terminal Growth Rate (TGR) | C6: 0.045 | D6: =Valuation!D16 -> 0.05 | E6: 0.055
B7: EV/EBITDA Exit Multiple | C7: 7.5 | D7: =Valuation!D43 -> 8.5 | E7: 9.5
B9: Sum PV FCFF (Rs Cr) | C9: =SUM('Scenario Assumptions'!E20:I20) -> 842.15085 | D9: =SUM('Scenario Assumptions'!K20:O20) -> 895.8218 | E9: =SUM('Scenario Assumptions'!Q20:U20) -> 908.82469
B10: PV of Terminal Value – GGM | C10: ='Scenario Assumptions'!I15*(1+C6)/(C5-C6)*'Scenario Assumptions'!I18 -> 1618.7361 | D10: ='Scenario Assumptions'!O15*(1+D6)/(D5-D6)*'Scenario Assumptions'!O18 -> 2723.0049 | E10: ='Scenario Assumptions'!U15*(1+E6)/(E5-E6)*'Scenario Assumptions'!U18 -> 4075.7327
B11: Enterprise Value – GGM (Rs Cr) | C11: =SUM(C9:C10) -> 2460.887 | D11: =SUM(D9:D10) -> 3618.8267 | E11: =SUM(E9:E10) -> 4984.5574
B12: PV of Terminal Value – Exit | C12: =C7*'Scenario Assumptions'!I9*'Scenario Assumptions'!I18 -> 2471.271 | D12: ='Valuation Summary'!D7*'Scenario Assumptions'!O9*'Scenario Assumptions'!O18 -> 4602.4519 | E12: ='Valuation Summary'!E7*'Scenario Assumptions'!U9*'Scenario Assumptions'!U18 -> 7171.6854
B13: Enterprise Value – Exit (Rs Cr) | C13: =C9+C12 -> 3313.4218 | D13: =D9+D12 -> 5498.2737 | E13: =E9+E12 -> 8080.5101
B14: Less: Net Debt & other adjustments | C14: =SUM(Valuation!H27:H31) -> -686.14 | D14: =C14 -> -686.14 | E14: =D14 -> -686.14
B15: Equity Value – GGM (Rs Cr) | C15: =MAX(0,C11+C14) -> 1774.747 | D15: =MAX(0,D11+D14) -> 2932.6867 | E15: =MAX(0,E11+E14) -> 4298.4174
B16: Equity Value – Exit (Rs Cr) | C16: =C13+C14 -> 2627.2818 | D16: =D13+D14 -> 4812.1337 | E16: =E13+E14 -> 7394.3701
B17: Shares Outstanding | C17: =Valuation!E33 -> 24433012 | D17: =C17 -> 24433012 | E17: =D17 -> 24433012 | G17: Weight
B18: Implied Price – GGM (Rs/share) | C18: =C15*10^7/C17 -> 726.37257 | D18: =D15*10^7/D17 -> 1200.2968 | E18: =E15*10^7/E17 -> 1759.2663 | G18: 0.6
B19: Implied Price – Exit (Rs/share) | C19: =C16*10^7/C17 -> 1075.3 | D19: =D16*10^7/D17 -> 1969.5213 | E19: =E16*10^7/E17 -> 3026.385 | G19: 0.4
B20: AVERAGE Price (Rs/share) | C20: =C18*$G$18+C19*$G$19 -> 865.94355 | D20: =D18*$G$18+D19*$G$19 -> 1507.9866 | E20: =E18*$G$18+E19*$G$19 -> 2266.1138
B22: Current Share Price | C22: =Cover!D11 -> 1575.8 | D22: =C22 -> 1575.8 | E22: =D22 -> 1575.8

Sheet Assumptions
A2: (Unless Otherwise specified, all financials are in ₹ Cr) | D2: Units | E2: 45016 | F2: =EOMONTH(E2,12) -> 45382 | G2: =EOMONTH(F2,12) -> 45747 | H2: =EOMONTH(G2,12) -> 46112 | I2: =EOMONTH(H2,12) -> 46477 | J2: =EOMONTH(I2,12) -> 46843 | K2: =EOMONTH(J2,12) -> 47208 | L2: =EOMONTH(K2,12) -> 47573 | M2: =EOMONTH(L2,12) -> 47938
B4: INCOME STATEMENT ASSUMPTIONS
A6: A. | B6: Revenue Assumptions
B8: =IS!B5 -> Sale of Products | E8: =IS!E5 -> 4213.16 | F8: =IS!F5 -> 4479.96 | G8: =IS!G5 -> 4266.12 | H8: =IS!H5 -> 4914.0228 | I8: =I21*I$11 -> 5743.1546 | J8: =J21*J$11 -> 6679.3819 | K8: =K21*K$11 -> 7529.2094 | L8: =L21*L$11 -> 8527.6932 | M8: =M21*M$11 -> 9704.4906
B9: =IS!B6 -> Sale of Services | E9: =IS!E6 -> 29.9 | F9: =IS!F6 -> 102.66 | G9: =IS!G6 -> 137.92 | H9: =IS!H6 -> 158.86614 | I9: =I22*I$11 -> 231.00957 | J9: =J22*J$11 -> 315.20679 | K9: =K22*K$11 -> 408.3639 | L9: =L22*L$11 -> 523.29026 | M9: =M22*M$11 -> 665.45078
B10: =IS!B7 -> Other operating revenues | E10: =IS!E7 -> 408.09 | F10: =IS!F7 -> 394.68 | G10: =IS!G7 -> 340.36 | H10: =IS!H7 -> 392.05105 | I10: =I23*I$11 -> 442.76835 | J10: =J23*J$11 -> 510.3348 | K10: =K23*K$11 -> 570.00794 | L10: =L23*L$11 -> 639.57699 | M10: =M23*M$11 -> 720.90502
B11: =IS!B8 -> Total Revenue from Operations | E11: =SUM(E8:E10) -> 4651.15 | F11: =SUM(F8:F10) -> 4977.3 | G11: =SUM(G8:G10) -> 4744.4 | H11: =SUM(H8:H10) -> 5464.94 | I11: =H11*(1+I15) -> 6416.9325 | J11: =I11*(1+J15) -> 7504.9235 | K11: =J11*(1+K15) -> 8507.5812 | L11: =K11*(1+L15) -> 9690.5604 | M11: =L11*(1+M15) -> 11090.846
B13: Macro / Industry Volume Growth (%) | D13: % | F13: 0.070122443 | G13: -0.046792438 | H13: 0.15187168 | I13: 0.14 | J13: 0.13 | K13: 0.09 | L13: 0.09 | M13: 0.09
B14: Price / Premiumization Growth (%) | D14: % | F14: 0.02 | G14: 0.01 | H14: 0.03 | I14: 0.03 | J14: 0.035 | K14: 0.04 | L14: 0.045 | M14: 0.05
B15: Total Revenue Growth (%) | D15: % | F15: =(1+F13)*(1+F14)-1 -> 0.091524892 | G15: =(1+G13)*(1+G14)-1 -> -0.037260362 | H15: =(1+H13)*(1+H14)-1 -> 0.18642783 | I15: =(1+I13)*(1+I14)-1 -> 0.1742 | J15: =(1+J13)*(1+J14)-1 -> 0.16955 | K15: =(1+K13)*(1+K14)-1 -> 0.1336 | L15: =(1+L13)*(1+L14)-1 -> 0.13905 | M15: =(1+M13)*(1+M14)-1 -> 0.1445
B21: Product Revenue (% of Total Revenue) | D21: % | E21: =E8/E$11 -> 0.90583189 | F21: =F8/F$11 -> 0.90007836 | G21: =G8/G$11 -> 0.89919062 | H21: =H8/H$11 -> 0.89919062 | I21: 0.895 | J21: 0.89 | K21: 0.885 | L21: 0.88 | M21: 0.875
B22: Services Revenue (% of Total Revenue) | D22: % | E22: =E9/E$11 -> 0.0064285177 | F22: =F9/F$11 -> 0.02062564 | G22: =G9/G$11 -> 0.029070062 | H22: =H9/H$11 -> 0.029070062 | I22: 0.036 | J22: 0.042 | K22: 0.048 | L22: 0.054 | M22: 0.06
B23: Other Operating Revenue (% of Total Revenue) | D23: % | E23: =E10/E$11 -> 0.087739591 | F23: =F10/F$11 -> 0.079296004 | G23: =G10/G$11 -> 0.071739314 | H23: =H10/H$11 -> 0.071739314 | I23: 0.069 | J23: 0.068 | K23: 0.067 | L23: 0.066 | M23: 0.065
A26: B. | B26: Expenses Assumptions
B28: Raw Material Cost | E28: =IS!E11 -> 3478.58 | F28: =IS!F11 -> 3588.29 | G28: =IS!G11 -> 3260.8 | H28: =IS!H11 -> 3740.04 | I28: =I33*I$11 -> 4376.348 | J28: =J33*J$11 -> 5103.348 | K28: =K33*K$11 -> 5768.1401 | L28: =L33*L$11 -> 6550.8188 | M28: =M33*M$11 -> 7475.2305
B29: Work‑in‑progress (WIP) | E29: =IS!E12 -> -53.6 | F29: =IS!F12 -> 19.71 | G29: =IS!G12 -> 50.6 | H29: =IS!H12 -> -4.31 | I29: 10 | J29: 12 | K29: 14 | L29: 15 | M29: 16
B30: Employee benefit expense | E30: =IS!E13 -> 445.9 | F30: =IS!F13 -> 512.99 | G30: =IS!G13 -> 507.06 | H30: =IS!H13 -> 591.06 | I30: =I34*I$11 -> 693.02872 | J30: =J34*J$11 -> 818.03666 | K30: =K34*K$11 -> 927.32635 | L30: =L34*L$11 -> 1065.9616 | M30: =M34*M$11 -> 1219.9931
B31: Other Expenses | E31: =IS!E14 -> 561.79 | F31: =IS!F14 -> 590.44 | G31: =IS!G14 -> 573.45 | H31: =IS!H14 -> 725.33 | I31: =I35*I$11 -> 821.36737 | J31: =J35*J$11 -> 945.62036 | K31: =K35*K$11 -> 1054.9401 | L31: =L35*L$11 -> 1182.2484 | M31: =M35*M$11 -> 1330.9016
B33: Raw Material Cost (% of Revenue) | D33: % | E33: =E28/E$11 -> 0.74789676 | F33: =F28/F$11 -> 0.72093103 | G33: =G28/G$11 -> 0.68729449 | H33: =H28/H$11 -> 0.68436982 | I33: 0.682 | J33: 0.68 | K33: 0.678 | L33: 0.676 | M33: 0.674
B34: Employee Benefit Expense (% of Revenue) | D34: % | E34: =E30/E$11 -> 0.095868764 | F34: =F30/F$11 -> 0.10306592 | G34: =G30/G$11 -> 0.10687547 | H34: =H30/H$11 -> 0.10815489 | I34: 0.108 | J34: 0.109 | K34: 0.109 | L34: 0.11 | M34: 0.11
B35: Other Expenses (% of Revenue) | D35: % | E35: =E31/E$11 -> 0.12078518 | F35: =F31/F$11 -> 0.11862656 | G35: =G31/G$11 -> 0.12086881 | H35: =H31/H$11 -> 0.13272424 | I35: 0.128 | J35: 0.126 | K35: 0.124 | L35: 0.122 | M35: 0.12
B37: Effective Tax Rate (%) | D37: % | E37: =IS!E26/IS!E25 -> 0.21793761 | F37: =IS!F26/IS!F25 -> 0.21309285 | G37: =IS!G26/IS!G25 -> 0.2465413 | H37: =IS!H26/IS!H25 -> 0.2545373 | I37: 0.2517 | J37: =I37 -> 0.2517 | K37: =J37 -> 0.2517 | L37: =K37 -> 0.2517 | M37: =L37 -> 0.2517
B40: BALANCE SHEET ASSUMPTIONS
A42: C. | B42: WORKING CAPITAL ASSUMPTIONS (Days-Based)
B44: COGS | E44: =SUM(E28:E31) -> 4432.67 | F44: =SUM(F28:F31) -> 4711.43 | G44: =SUM(G28:G31) -> 4391.91 | H44: =SUM(H28:H31) -> 5052.12 | I44: =SUM(I28:I31) -> 5900.7441 | J44: =SUM(J28:J31) -> 6879.005 | K44: =SUM(K28:K31) -> 7764.4065 | L44: =SUM(L28:L31) -> 8814.0288 | M44: =SUM(M28:M31) -> 10042.125
B46: Receivable Days (DSO) | D46: # days | E46: =BS!F10/E11*365 -> 56.999688 | F46: =BS!G10/F11*365 -> 58.726478 | G46: =BS!H10/G11*365 -> 62.907185 | H46: =BS!I10/H11*365 -> 64.581 | I46: 55 | J46: 56 | K46: 54 | L46: 57 | M46: 60
B47: Inventory Days (DIO) | D47: # days | E47: =BS!F11/Assumptions!E44*365 -> 72.667828 | F47: =BS!G11/Assumptions!F44*365 -> 59.577655 | G47: =BS!H11/Assumptions!G44*365 -> 62.033819 | H47: =BS!I11/Assumptions!H44*365 -> 64.238562 | I47: 55 | J47: 54 | K47: 57 | L47: 55 | M47: 56
B48: Payable Days (DPO) | D48: # days | E48: =BS!E32/E44*365 -> 95.894359 | F48: =BS!F32/F44*365 -> 92.738415 | G48: =BS!G32/G44*365 -> 101.49818 | H48: =BS!H32/H44*365 -> 96.679354 | I48: 97 | J48: 97 | K48: 97 | L48: 97 | M48: 97
B49: Other Current Assets (% of Revenue) | D49: % | E49: =BS!E12/E11 -> 0.033838943 | F49: =BS!F12/F11 -> 0.03487232 | G49: =BS!G12/G11 -> 0.036114156 | H49: =BS!H12/H11 -> 0.043184372 | I49: 0.04 | J49: 0.038 | K49: 0.036 | L49: 0.035 | M49: 0.034
A52: D. | B52: Asset Schedule Assumptions
B54: Capex (before depreciation Adjustment) | E54: =-CF!E26 -> 151.27 | F54: =-CF!F26 -> 150.28 | G54: =-CF!G26 -> 209.26 | H54: =-CF!H26 -> 276.78 | I54: 300 | J54: 130 | K54: 105 | L54: 55 | M54: 0
B55: Asset Life (SLM Method) | E55: 25 | F55: =E55 -> 25 | G55: =F55 -> 25 | H55: =G55 -> 25 | I55: =H55 -> 25 | J55: =I55 -> 25 | K55: =J55 -> 25 | L55: =K55 -> 25 | M55: =L55 -> 25
B56: Disposal of Assets | E56: =CF!E24 -> 1.6 | F56: =CF!F24 -> 0.18 | G56: =CF!G24 -> 1.25 | H56: =CF!H24 -> 2.42 | I56: =AVERAGE(E56:H56) -> 1.3625 | J56: =AVERAGE(F56:I56) -> 1.303125 | K56: =AVERAGE(G56:J56) -> 1.5839062 | L56: =AVERAGE(H56:K56) -> 1.6673828 | M56: =AVERAGE(I56:L56) -> 1.4792285
B58: Other Non Current Assets (% of Revenue) | D58: % | E58: =BS!E21/E11 -> 0.006914419 | F58: =BS!F21/F11 -> 0.011544412 | G58: =BS!G21/G11 -> 0.010625158 | H58: =BS!H21/H11 -> 0.010378888 | I58: 0.009 | J58: 0.009 | K58: 0.009 | L58: 0.009 | M58: 0.009
A61: E. | B61: Financial Assumptions
B63: Interest Rate | D63: % | E63: 0.078 | F63: =E63*(1+I37) -> 0.0976326
B64: Long term borrowings | D64: ₹ Cr | E64: =BS!E38 -> 203.25 | F64: =BS!F38 -> 287.55 | G64: =BS!G38 -> 302.98 | H64: =BS!H38 -> 257.29 | I64: ='Debt Schedule'!I18 -> 248.645 | J64: ='Debt Schedule'!J18 -> 241.82307 | K64: ='Debt Schedule'!K18 -> 239.17488 | L64: ='Debt Schedule'!L18 -> 225.84165 | M64: ='Debt Schedule'!M18 -> 203.70773
B66: New Debt Issues
C67: Short term debt | D67: ₹ Cr | E67: =CF!E33 -> -25.11 | F67: =CF!F33 -> 11.53 | G67: =CF!G33 -> -115.73 | H67: =CF!H33 -> 19.06 | I67: -10.044535 | J67: -8.430407 | K67: 43.267262 | L67: 40.163286 | M67: 68.985791 | O67: <<--- Used Forecast formula to get these numbers based on historical trends only
C68: Long term Debt | D68: ₹ Cr | E68: 101.8 | F68: 117.86 | G68: 172.36 | H68: 107.09 | I68: =I69*'Asset Schedule'!I9 -> 120 | J68: =J69*'Asset Schedule'!J9 -> 129.93283 | K68: =K69*'Asset Schedule'!K9 -> 142.44565 | L68: =L69*'Asset Schedule'!L9 -> 142.13044 | M68: =M69*'Asset Schedule'!M9 -> 135.95523
...

Sheet Scenario Assumptions
E1: BEAR SCENARIO | K1: Base Scenario | Q1: BULL SCENARIO
A2: =IS!A2 -> (Unless Otherwise specified, all financials are in ₹ Cr) | E2: =IS!I2 -> 46477 | F2: =IS!J2 -> 46843 | G2: =IS!K2 -> 47208 | H2: =IS!L2 -> 47573 | I2: =IS!M2 -> 47938 | K2: =E2 -> 46477 | L2: =F2 -> 46843 | M2: =G2 -> 47208 | N2: =H2 -> 47573 | O2: =I2 -> 47938 | Q2: =K2 -> 46477 | R2: =L2 -> 46843 | S2: =M2 -> 47208 | T2: =N2 -> 47573 | U2: =O2 -> 47938
C4: Revenue Growth YoY (%) | E4: 0.06 | F4: 0.07 | G4: 0.075 | H4: 0.07 | I4: 0.07 | K4: =Assumptions!I15 -> 0.1742 | L4: =Assumptions!J15 -> 0.16955 | M4: =Assumptions!K15 -> 0.1336 | N4: =Assumptions!L15 -> 0.13905 | O4: =Assumptions!M15 -> 0.1445 | Q4: 0.22 | R4: 0.22 | S4: 0.2 | T4: 0.18 | U4: 0.175
C5: Revenue (Rs Cr) | E5: 5793 | F5: 6198 | G5: 6663 | H5: 7130 | I5: 7629 | K5: =Assumptions!I11 -> 6416.9325 | L5: =Assumptions!J11 -> 7504.9235 | M5: =Assumptions!K11 -> 8507.5812 | N5: =Assumptions!L11 -> 9690.5604 | O5: =Assumptions!M11 -> 11090.846 | Q5: 6667 | R5: 8134 | S5: 9761 | T5: 11518 | U5: 13533
C7: Revenue | E7: =E5 -> 5793 | F7: =F5 -> 6198 | G7: =G5 -> 6663 | H7: =H5 -> 7130 | I7: =I5 -> 7629 | K7: =K5 -> 6416.9325 | L7: =L5 -> 7504.9235 | M7: =M5 -> 8507.5812 | N7: =N5 -> 9690.5604 | O7: =O5 -> 11090.846 | Q7: =Q5 -> 6667 | R7: =R5 -> 8134 | S7: =S5 -> 9761 | T7: =T5 -> 11518 | U7: =U5 -> 13533
C8: EBITDA% | E8: 0.072 | F8: 0.075 | G8: 0.078 | H8: 0.082 | I8: 0.085 | K8: =IS!I18 -> 0.080441623 | L8: =IS!J18 -> 0.08340105 | M8: =IS!K18 -> 0.087354409 | N8: =IS!L18 -> 0.090452102 | O8: =IS!M18 -> 0.094557369 | Q8: 0.09 | R8: 0.094 | S8: 0.097 | T8: 0.1 | U8: 0.106
C9: EBITDA | E9: =E7*E8 -> 417.096 | F9: =F7*F8 -> 464.85 | G9: =G7*G8 -> 519.714 | H9: =H7*H8 -> 584.66 | I9: =I7*I8 -> 648.465 | K9: =K7*K8 -> 516.18847 | L9: =L7*L8 -> 625.91849 | M9: =M7*M8 -> 743.17473 | N9: =N7*N8 -> 876.53156 | O9: =O7*O8 -> 1048.7213 | Q9: =Q8*Q7 -> 600.03 | R9: =R8*R7 -> 764.596 | S9: =S8*S7 -> 946.817 | T9: =T8*T7 -> 1151.8 | U9: =U8*U7 -> 1434.498
C10: Depreciation | E10: =K10 -> 105.0256 | F10: =L10 -> 116.83767 | G10: =M10 -> 128.70815 | H10: =N10 -> 139.64126 | I10: =O10 -> 149.35234 | K10: =IS!I19 -> 105.0256 | L10: =IS!J19 -> 116.83767 | M10: =IS!K19 -> 128.70815 | N10: =IS!L19 -> 139.64126 | O10: =IS!M19 -> 149.35234 | Q10: =K10 -> 105.0256 | R10: =L10 -> 116.83767 | S10: =M10 -> 128.70815 | T10: =N10 -> 139.64126 | U10: =O10 -> 149.35234
C11: EBIT | E11: =E9-E10 -> 312.0704 | F11: =F9-F10 -> 348.01232 | G11: =G9-G10 -> 391.00585 | H11: =H9-H10 -> 445.01874 | I11: =I9-I10 -> 499.11266 | K11: =K9-K10 -> 411.16287 | L11: =L9-L10 -> 509.08082 | M11: =M9-M10 -> 614.46658 | N11: =N9-N10 -> 736.8903 | O11: =O9-O10 -> 899.36891 | Q11: =Q9-Q10 -> 495.0044 | R11: =R9-R10 -> 647.75833 | S11: =S9-S10 -> 818.10885 | T11: =T9-T10 -> 1012.1587 | U11: =U9-U10 -> 1285.1457
C12: NOPAT | E12: =E11*(1-Assumptions!$I$37) -> 233.52228 | F12: =F11*(1-Assumptions!$I$37) -> 260.41762 | G12: =G11*(1-Assumptions!$I$37) -> 292.58968 | H12: =H11*(1-Assumptions!$I$37) -> 333.00753 | I12: =I11*(1-Assumptions!$I$37) -> 373.486 | K12: =K11*(1-Assumptions!$I$37) -> 307.67317 | L12: =L11*(1-Assumptions!$I$37) -> 380.94518 | M12: =M11*(1-Assumptions!$I$37) -> 459.80535 | N12: =N11*(1-Assumptions!$I$37) -> 551.41501 | O12: =O11*(1-Assumptions!$I$37) -> 672.99775 | Q12: =Q11*(1-Assumptions!$I$37) -> 370.41179 | R12: =R11*(1-Assumptions!$I$37) -> 484.71755 | S12: =S11*(1-Assumptions!$I$37) -> 612.19086 | T12: =T11*(1-Assumptions!$I$37) -> 757.39839 | U12: =U11*(1-Assumptions!$I$37) -> 961.67449
C13: ΔWorking Capital | E13: =K13*0.8 -> -10.450875 | F13: =L13*0.8 -> -1.9201232 | G13: =M13*0.8 -> -7.7068397 | H13: =N13*0.8 -> -24.263412 | I13: =O13*0.8 -> -96.599042 | K13: =CF!I18 -> -13.063593 | L13: =CF!J18 -> -2.400154 | M13: =CF!K18 -> -9.6335497 | N13: =CF!L18 -> -30.329265 | O13: =CF!M18 -> -120.7488 | Q13: =K13*1.2 -> -15.676312 | R13: =L13*1.2 -> -2.8801847 | S13: =M13*1.2 -> -11.56026 | T13: =N13*1.2 -> -36.395118 | U13: =O13*1.2 -> -144.89856
C14: Capex | E14: =K14*0.5 -> -150 | F14: =L14*0.5 -> -147.65094 | G14: =M14*0.5 -> -148.38088 | H14: =N14*0.5 -> -136.66388 | I14: =O14*0.5 -> -121.3886 | K14: =-'Asset Schedule'!I9 -> -300 | L14: =-'Asset Schedule'!J9 -> -295.30187 | M14: =-'Asset Schedule'!K9 -> -296.76176 | N14: =-'Asset Schedule'!L9 -> -273.32777 | O14: =-'Asset Schedule'!M9 -> -242.7772 | Q14: =K14*1.5 -> -450 | R14: =L14*1.5 -> -442.95281 | S14: =M14*1.5 -> -445.14264 | T14: =N14*1.5 -> -409.99165 | U14: =O14*1.5 -> -364.16581
C15: FCFF | E15: =E12+E10+E13+E14 -> 178.09701 | F15: =F12+F10+F13+F14 -> 227.68424 | G15: =G12+G10+G13+G14 -> 265.21011 | H15: =H12+H10+H13+H14 -> 311.72149 | I15: =I12+I10+I13+I14 -> 304.8507 | K15: =K12+K10+K13+K14 -> 99.635181 | L15: =L12+L10+L13+L14 -> 200.08082 | M15: =M12+M10+M13+M14 -> 282.11818 | N15: =N12+N10+N13+N14 -> 387.39923 | O15: =O12+O10+O13+O14 -> 458.82409 | Q15: =Q12+Q10+Q13+Q14 -> 9.7610804 | R15: =R12+R10+R13+R14 -> 155.72223 | S15: =S12+S10+S13+S14 -> 284.1961 | T15: =T12+T10+T13+T14 -> 450.65287 | U15: =U12+U10+U13+U14 -> 601.96247
C17: No. of Years | E17: 1 | F17: 2 | G17: 3 | H17: 4 | I17: 5 | K17: 1 | L17: 2 | M17: 3 | N17: 4 | O17: 5 | Q17: 1 | R17: 2 | S17: 3 | T17: 4 | U17: 5
C18: Discount Factor | E18: =1/(1+'Valuation Summary'!$C$5)^E17 -> 0.87336245 | F18: =1/(1+'Valuation Summary'!$C$5)^F17 -> 0.76276196 | G18: =1/(1+'Valuation Summary'!$C$5)^G17 -> 0.66616765 | H18: =1/(1+'Valuation Summary'!$C$5)^H17 -> 0.58180581 | I18: =1/(1+'Valuation Summary'!$C$5)^I17 -> 0.50812734 | K18: =1/(1+'Valuation Summary'!$D$5)^K17 -> 0.87615724 | L18: =1/(1+'Valuation Summary'!$D$5)^L17 -> 0.7676515 | M18: =1/(1+'Valuation Summary'!$D$5)^M17 -> 0.67258342 | N18: =1/(1+'Valuation Summary'!$D$5)^N17 -> 0.58928883 | O18: =1/(1+'Valuation Summary'!$D$5)^O17 -> 0.51630967 | Q18: =1/(1+'Valuation Summary'!$E$5)^Q17 -> 0.87950748 | R18: =1/(1+'Valuation Summary'!$E$5)^R17 -> 0.7735334 | S18: =1/(1+'Valuation Summary'!$E$5)^S17 -> 0.68032841 | T18: =1/(1+'Valuation Summary'!$E$5)^T17 -> 0.59835392 | U18: =1/(1+'Valuation Summary'!$E$5)^U17 -> 0.52625675
C20: PV of FCFF | E20: =E18*E15 -> 155.54324 | F20: =F18*F15 -> 173.66888 | G20: =G18*G15 -> 176.67439 | H20: =H18*H15 -> 181.36137 | I20: =I18*I15 -> 154.90298 | K20: =K18*K15 -> 87.296085 | L20: =L18*L15 -> 153.59234 | M20: =M18*M15 -> 189.74801 | N20: =N18*N15 -> 228.29004 | O20: =O18*O15 -> 236.89532 | Q20: =Q18*Q15 -> 8.5849432 | R20: =R18*R15 -> 120.45635 | S20: =S18*S15 -> 193.34668 | T20: =T18*T15 -> 269.64991 | U20: =U18*U15 -> 316.78681

Sheet Asset Schedule
A2: =Assumptions!A2 -> (Unless Otherwise specified, all financials are in ₹ Cr) | C2: Units | E2: =Assumptions!E2 -> 45016 | F2: =Assumptions!F2 -> 45382 | G2: =Assumptions!G2 -> 45747 | H2: =Assumptions!H2 -> 46112 | I2: =Assumptions!I2 -> 46477 | J2: =Assumptions!J2 -> 46843 | K2: =Assumptions!K2 -> 47208 | L2: =Assumptions!L2 -> 47573 | M2: =Assumptions!M2 -> 47938
B4: Depreciation Method | C4: SLM
B5: Asset Life | C5: Years | E5: =Assumptions!E55 -> 25 | F5: =Assumptions!F55 -> 25 | G5: =Assumptions!G55 -> 25 | H5: =Assumptions!H55 -> 25 | I5: =Assumptions!I55 -> 25 | J5: =Assumptions!J55 -> 25 | K5: =Assumptions!K55 -> 25 | L5: =Assumptions!L55 -> 25 | M5: =Assumptions!M55 -> 25
B6: Disposal of Assets | C6: ₹ Cr | E6: =Assumptions!E56 -> 1.6 | F6: =Assumptions!F56 -> 0.18 | G6: =Assumptions!G56 -> 1.25 | H6: =Assumptions!H56 -> 2.42 | I6: =Assumptions!I56 -> 1.3625 | J6: =Assumptions!J56 -> 1.303125 | K6: =Assumptions!K56 -> 1.5839062 | L6: =Assumptions!L56 -> 1.6673828 | M6: =Assumptions!M56 -> 1.4792285
B8: Capex (before depreciation Adjustment) | I8: =Assumptions!I54 -> 300 | J8: =Assumptions!J54 -> 130 | K8: =Assumptions!K54 -> 105 | L8: =Assumptions!L54 -> 55 | M8: =Assumptions!M54 -> 0
B9: Capex | C9: ₹ Cr | E9: =Assumptions!E54 -> 151.27 | F9: =Assumptions!F54 -> 150.28 | G9: =Assumptions!G54 -> 209.26 | H9: =Assumptions!H54 -> 276.78 | I9: =Assumptions!I54 -> 300 | J9: =9%*I29+J8 -> 295.30187 | K9: =9%*J29+K8 -> 296.76176 | L9: =9%*K29+L8 -> 273.32777 | M9: =9%*L29+M8 -> 242.7772
A11: Depreciation Schedule
B13: 45016 | E13: =E$9/E$5 -> 6.0508 | F13: =E13 -> 6.0508 | G13: =F13 -> 6.0508 | H13: =G13 -> 6.0508 | I13: =H13 -> 6.0508 | J13: =I13 -> 6.0508 | K13: =J13 -> 6.0508 | L13: =K13 -> 6.0508 | M13: =L13 -> 6.0508
B14: 45382 | F14: =F$9/F$5 -> 6.0112 | G14: =F14 -> 6.0112 | H14: =G14 -> 6.0112 | I14: =H14 -> 6.0112 | J14: =I14 -> 6.0112 | K14: =J14 -> 6.0112 | L14: =K14 -> 6.0112 | M14: =L14 -> 6.0112
B15: 45747 | G15: =G$9/G$5 -> 8.3704 | H15: =G15 -> 8.3704 | I15: =H15 -> 8.3704 | J15: =I15 -> 8.3704 | K15: =J15 -> 8.3704 | L15: =K15 -> 8.3704 | M15: =L15 -> 8.3704
B16: 46112 | H16: =H$9/H$5 -> 11.0712 | I16: =H16 -> 11.0712 | J16: =I16 -> 11.0712 | K16: =J16 -> 11.0712 | L16: =K16 -> 11.0712 | M16: =L16 -> 11.0712
B17: 46477 | I17: =I$9/I$5 -> 12 | J17: =I17 -> 12 | K17: =J17 -> 12 | L17: =K17 -> 12 | M17: =L17 -> 12
B18: 46843 | J18: =J$9/J$5 -> 11.812075 | K18: =J18 -> 11.812075 | L18: =K18 -> 11.812075 | M18: =L18 -> 11.812075
B19: 47208 | K19: =K$9/K$5 -> 11.870471 | L19: =K19 -> 11.870471 | M19: =L19 -> 11.870471
B20: 47573 | L20: =L$9/L$5 -> 10.933111 | M20: =L20 -> 10.933111
B21: 47938 | M21: =M$9/M$5 -> 9.7110882
B23: Total Depreciation | E23: =SUM(E13:E22) -> 6.0508 | F23: =SUM(F13:F22) -> 12.062 | G23: =SUM(G13:G22) -> 20.4324 | H23: =SUM(H13:H22) -> 31.5036 | I23: =SUM(I13:I22) -> 43.5036 | J23: =SUM(J13:J22) -> 55.315675 | K23: =SUM(K13:K22) -> 67.186145 | L23: =SUM(L13:L22) -> 78.119256 | M23: =SUM(M13:M22) -> 87.830344
A25: Gross Block
B26: Opening Balance | I26: =H29 -> 1538.05 | J26: =I29 -> 1836.6875 | K26: =J29 -> 2130.6863 | L26: =K29 -> 2425.8641 | M26: =L29 -> 2697.5245
B27: Add: Capex | I27: =I9 -> 300 | J27: =J9 -> 295.30187 | K27: =K9 -> 296.76176 | L27: =L9 -> 273.32777 | M27: =M9 -> 242.7772
B28: Less: Assets Sold/ Disposed | I28: =I6 -> 1.3625 | J28: =J6 -> 1.303125 | K28: =K6 -> 1.5839062 | L28: =L6 -> 1.6673828 | M28: =M6 -> 1.4792285
B29: Closing Balance | H29: =BS!H17 -> 1538.05 | I29: =I26+I27-I28 -> 1836.6875 | J29: =J26+J27-J28 -> 2130.6863 | K29: =K26+K27-K28 -> 2425.8641 | L29: =L26+L27-L28 -> 2697.5245 | M29: =M26+M27-M28 -> 2938.8225
B31: Existing Block Depreciation | I31: =$H$29/I5 -> 61.522 | J31: =$H$29/J5 -> 61.522 | K31: =$H$29/K5 -> 61.522 | L31: =$H$29/L5 -> 61.522 | M31: =$H$29/M5 -> 61.522
B32: New Capex Depreciation | I32: =I23 -> 43.5036 | J32: =J23 -> 55.315675 | K32: =K23 -> 67.186145 | L32: =L23 -> 78.119256 | M32: =M23 -> 87.830344
A34: Accumulated Depreciation
B35: Opening Balance | I35: =H37 -> 115.28 | J35: =I37 -> 220.3056 | K35: =J37 -> 337.14328 | L35: =K37 -> 465.85142 | M35: =L37 -> 605.49268
B36: Add: Depreciation during current year | I36: =I31+I32 -> 105.0256 | J36: =J31+J32 -> 116.83767 | K36: =K31+K32 -> 128.70815 | L36: =L31+L32 -> 139.64126 | M36: =M31+M32 -> 149.35234
B37: Closing Balance | H37: =IS!H19 -> 115.28 | I37: =I35+I36 -> 220.3056 | J37: =J35+J36 -> 337.14328 | K37: =K35+K36 -> 465.85142 | L37: =L35+L36 -> 605.49268 | M37: =M35+M36 -> 754.84502

Sheet Debt Schedule
A2: =Assumptions!A2 -> (Unless Otherwise specified, all financials are in ₹ Cr) | C2: Units | E2: =Assumptions!E2 -> 45016 | F2: =Assumptions!F2 -> 45382 | G2: =Assumptions!G2 -> 45747 | H2: =Assumptions!H2 -> 46112 | I2: =Assumptions!I2 -> 46477 | J2: =Assumptions!J2 -> 46843 | K2: =Assumptions!K2 -> 47208 | L2: =Assumptions!L2 -> 47573 | M2: =Assumptions!M2 -> 47938
A4: Short term borrowings
B5: Opening Balance | I5: =H8 -> 454.36 | J5: =I8 -> 444.31546 | K5: =J8 -> 435.88506 | L5: =K8 -> 479.15232 | M5: =L8 -> 519.31561
B6: Add: New Issued | I6: =Assumptions!I67 -> -10.044535 | J6: =Assumptions!J67 -> -8.430407 | K6: =Assumptions!K67 -> 43.267262 | L6: =Assumptions!L67 -> 40.163286 | M6: =Assumptions!M67 -> 68.985791
B7: Less: Repayments | I7: =-Assumptions!I72 -> 0 | J7: =-Assumptions!J72 -> 0 | K7: =-Assumptions!K72 -> 0 | L7: =-Assumptions!L72 -> 0 | M7: =-Assumptions!M72 -> 0
B8: Closing Balance | H8: =BS!H31 -> 454.36 | I8: =SUM(I5:I7) -> 444.31546 | J8: =SUM(J5:J7) -> 435.88506 | K8: =SUM(K5:K7) -> 479.15232 | L8: =SUM(L5:L7) -> 519.31561 | M8: =SUM(M5:M7) -> 588.3014
B10: Average Loan Outstanding | I10: =AVERAGE(H8:I8) -> 449.33773 | J10: =AVERAGE(I8:J8) -> 440.10026 | K10: =AVERAGE(J8:K8) -> 457.51869 | L10: =AVERAGE(K8:L8) -> 499.23396 | M10: =AVERAGE(L8:M8) -> 553.8085
B11: Interest Rate | I11: =Assumptions!F63 -> 0.0976326 | J11: =I11 -> 0.0976326 | K11: =J11 -> 0.0976326 | L11: =K11 -> 0.0976326 | M11: =L11 -> 0.0976326
B12: Interest Expense | I12: =I11*I10 -> 43.870011 | J12: =J11*J10 -> 42.968133 | K12: =K11*K10 -> 44.668739 | L12: =L11*L10 -> 48.74151 | M12: =M11*M10 -> 54.069764
A14: Long term borrowings
B15: Opening Balance | I15: =H18 -> 257.29 | J15: =I18 -> 248.645 | K15: =J18 -> 241.82307 | L15: =K18 -> 239.17488 | M15: =L18 -> 225.84165
B16: Add: New Issued | I16: =Assumptions!I68 -> 120 | J16: =Assumptions!J68 -> 129.93283 | K16: =Assumptions!K68 -> 142.44565 | L16: =Assumptions!L68 -> 142.13044 | M16: =Assumptions!M68 -> 135.95523
B17: Less: Repayments | I17: =Assumptions!I73 -> -128.645 | J17: =Assumptions!J73 -> -136.75475 | K17: =Assumptions!K73 -> -145.09384 | L17: =Assumptions!L73 -> -155.46367 | M17: =Assumptions!M73 -> -158.08915
B18: Closing Balance | H18: =BS!H38 -> 257.29 | I18: =SUM(I15:I17) -> 248.645 | J18: =SUM(J15:J17) -> 241.82307 | K18: =SUM(K15:K17) -> 239.17488 | L18: =SUM(L15:L17) -> 225.84165 | M18: =SUM(M15:M17) -> 203.70773
B20: Average Loan Outstanding | I20: =AVERAGE(H18:I18) -> 252.9675 | J20: =AVERAGE(I18:J18) -> 245.23404 | K20: =AVERAGE(J18:K18) -> 240.49898 | L20: =AVERAGE(K18:L18) -> 232.50826 | M20: =AVERAGE(L18:M18) -> 214.77469
B21: Interest Rate | I21: =I11 -> 0.0976326 | J21: =J11 -> 0.0976326 | K21: =K11 -> 0.0976326 | L21: =L11 -> 0.0976326 | M21: =M11 -> 0.0976326
B22: Interest Expense | I22: =I21*I20 -> 24.697875 | J22: =J21*J20 -> 23.942837 | K22: =K21*K20 -> 23.48054 | L22: =L21*L20 -> 22.700386 | M22: =M21*M20 -> 20.969011
A24: Lease Liabilities
B25: Opening Balance | I25: =H29 -> 56.47 | J25: =I29 -> 41.4229 | K25: =J29 -> 25.322503 | L25: =K29 -> 8.0950782 | M25: =L29 -> 0
B26: Interest | I26: =Assumptions!I78*I25 -> 3.9529 | J26: =Assumptions!J78*J25 -> 2.899603 | K26: =Assumptions!K78*K25 -> 1.7725752 | L26: =Assumptions!L78*L25 -> 0.56665547 | M26: =Assumptions!M78*M25 -> 0
B27: Total Payment | I27: =Assumptions!I77 -> 19 | J27: =Assumptions!J77 -> 19 | K27: =Assumptions!K77 -> 19 | L27: =Assumptions!L77 -> 8.6617337 | M27: =Assumptions!M77 -> 0
B28: Principal Paid | I28: =I27-I26 -> 15.0471 | J28: =J27-J26 -> 16.100397 | K28: =K27-K26 -> 17.227425 | L28: =L27-L26 -> 8.0950782 | M28: =M27-M26 -> 0
B29: Closing Balance | H29: =BS!H37 -> 56.47 | I29: =MAX(0,I25-I28) -> 41.4229 | J29: =MAX(0,J25-J28) -> 25.322503 | K29: =MAX(0,K25-K28) -> 8.0950782 | L29: =MAX(0,L25-L28) -> 0 | M29: =MAX(0,M25-M28) -> 0
B32: Total Interest Expense | I32: =I12+I22+I26 -> 72.520786 | J32: =J12+J22+J26 -> 69.810572 | K32: =K12+K22+K26 -> 69.921855 | L32: =L12+L22+L26 -> 72.008551 | M32: =M12+M22+M26 -> 75.038775

Sheet IS
A2: (Unless Otherwise specified, all financials are in ₹ Cr) | E2: 45016 | F2: =EOMONTH(E2,12) -> 45382 | G2: =EOMONTH(F2,12) -> 45747 | H2: =EOMONTH(G2,12) -> 46112 | I2: =EOMONTH(H2,12) -> 46477 | J2: =EOMONTH(I2,12) -> 46843 | K2: =EOMONTH(J2,12) -> 47208 | L2: =EOMONTH(K2,12) -> 47573 | M2: =EOMONTH(L2,12) -> 47938 | P2: Q1 FY26 | Q2: Q2 FY26 | R2: Q3 FY26 | S2: Q4 FY26
A4: Revenue from Operations
B5: Sale of Products | E5: 4213.16 | F5: 4479.96 | G5: 4266.12 | H5: =SUM(P5:S5) -> 4914.0228 | I5: =Assumptions!I8 -> 5743.1546 | J5: =Assumptions!J8 -> 6679.3819 | K5: =Assumptions!K8 -> 7529.2094 | L5: =Assumptions!L8 -> 8527.6932 | M5: =Assumptions!M8 -> 9704.4906 | P5: 1137.9257 | Q5: 1136.55 | R5: 1233.195 | S5: 1406.3521
B6: Sale of Services | E6: 29.9 | F6: 102.66 | G6: 137.92 | H6: =SUM(P6:S6) -> 158.86614 | I6: =Assumptions!I9 -> 231.00957 | J6: =Assumptions!J9 -> 315.20679 | K6: =Assumptions!K9 -> 408.3639 | L6: =Assumptions!L9 -> 523.29026 | M6: =Assumptions!M9 -> 665.45078 | P6: 36.788163 | Q6: 36.743686 | R6: 39.868136 | S6: 45.466158
B7: Other operating revenues | E7: 408.09 | F7: 394.68 | G7: 340.36 | H7: =SUM(P7:S7) -> 392.05105 | I7: =Assumptions!I10 -> 442.76835 | J7: =Assumptions!J10 -> 510.3348 | K7: =Assumptions!K10 -> 570.00794 | L7: =Assumptions!L10 -> 639.57699 | M7: =Assumptions!M10 -> 720.90502 | P7: 90.786102 | Q7: 90.67634 | R7: 98.386882 | S7: 112.20172
B8: Total Revenue from Operations | E8: =SUM(E5:E7) -> 4651.15 | F8: =SUM(F5:F7) -> 4977.3 | G8: =SUM(G5:G7) -> 4744.4 | H8: =SUM(H5:H7) -> 5464.94 | I8: =SUM(I5:I7) -> 6416.9325 | J8: =SUM(J5:J7) -> 7504.9235 | K8: =SUM(K5:K7) -> 8507.5812 | L8: =SUM(L5:L7) -> 9690.5604 | M8: =SUM(M5:M7) -> 11090.846 | P8: 1265.5 | Q8: 1263.97 | R8: 1371.45 | S8: 1564.02
A10: Operating Costs
B11: Raw Material Cost | E11: 3478.58 | F11: 3588.29 | G11: 3260.8 | H11: =SUM(P11:S11) -> 3740.04 | I11: =Assumptions!I28 -> 4376.348 | J11: =Assumptions!J28 -> 5103.348 | K11: =Assumptions!K28 -> 5768.1401 | L11: =Assumptions!L28 -> 6550.8188 | M11: =Assumptions!M28 -> 7475.2305 | P11: 841.31 | Q11: 938.47 | R11: 932.26 | S11: 1028
B12: Work‑in‑progress (WIP) | E12: -53.6 | F12: 19.71 | G12: 50.6 | H12: =SUM(P12:S12) -> -4.31 | I12: =Assumptions!I29 -> 10 | J12: =Assumptions!J29 -> 12 | K12: =Assumptions!K29 -> 14 | L12: =Assumptions!L29 -> 15 | M12: =Assumptions!M29 -> 16 | P12: 31.82 | Q12: -77.5 | R12: 20.68 | S12: 20.69
B13: Employee benefit expense | E13: 445.9 | F13: 512.99 | G13: 507.06 | H13: =SUM(P13:S13) -> 591.06 | I13: =Assumptions!I30 -> 693.02872 | J13: =Assumptions!J30 -> 818.03666 | K13: =Assumptions!K30 -> 927.32635 | L13: =Assumptions!L30 -> 1065.9616 | M13: =Assumptions!M30 -> 1219.9931 | P13: 140.11 | Q13: 146.68 | R13: 151.68 | S13: 152.59
B14: Other Expenses | E14: 561.79 | F14: 590.44 | G14: 573.45 | H14: =SUM(P14:S14) -> 725.33 | I14: =Assumptions!I31 -> 821.36737 | J14: =Assumptions!J31 -> 945.62036 | K14: =Assumptions!K31 -> 1054.9401 | L14: =Assumptions!L31 -> 1182.2484 | M14: =Assumptions!M31 -> 1330.9016 | P14: 158.61 | Q14: 163.72 | R14: 166.62 | S14: 236.38
B15: Total Operating Costs | E15: =SUM(E11:E14) -> 4432.67 | F15: =SUM(F11:F14) -> 4711.43 | G15: =SUM(G11:G14) -> 4391.91 | H15: =SUM(H11:H14) -> 5052.12 | I15: =SUM(I11:I14) -> 5900.7441 | J15: =SUM(J11:J14) -> 6879.005 | K15: =SUM(K11:K14) -> 7764.4065 | L15: =SUM(L11:L14) -> 8814.0288 | M15: =SUM(M11:M14) -> 10042.125 | P15: =SUM(P11:P14) -> 1171.85 | Q15: =SUM(Q11:Q14) -> 1171.37 | R15: =SUM(R11:R14) -> 1271.24 | S15: =SUM(S11:S14) -> 1437.66
A17: EBITDA | E17: =E8-E15 -> 218.48 | F17: =F8-F15 -> 265.87 | G17: =G8-G15 -> 352.49 | H17: =H8-H15 -> 412.82 | I17: =I8-I15 -> 516.18847 | J17: =J8-J15 -> 625.91849 | K17: =K8-K15 -> 743.17473 | L17: =L8-L15 -> 876.53156 | M17: =M8-M15 -> 1048.7213 | P17: =P8-P15 -> 93.65 | Q17: =Q8-Q15 -> 92.6 | R17: =R8-R15 -> 100.21 | S17: =S8-S15 -> 126.36
A18: EBITDA Margin | E18: =E17/E8 -> 0.046973329 | F18: =F17/F8 -> 0.053416511 | G18: =G17/G8 -> 0.074296012 | H18: =H17/H8 -> 0.075539713 | I18: =I17/I8 -> 0.080441623 | J18: =J17/J8 -> 0.08340105 | K18: =K17/K8 -> 0.087354409 | L18: =L17/L8 -> 0.090452102 | M18: =M17/M8 -> 0.094557369 | P18: =P17/P8 -> 0.074002371 | Q18: =Q17/Q8 -> 0.073261232 | R18: =R17/R8 -> 0.07306865 | S18: =S17/S8 -> 0.080791806
B19: Depreciation | E19: 72.14 | F19: 84.91 | G19: 93.22 | H19: =SUM(P19:S19) -> 115.28 | I19: ='Asset Schedule'!I36 -> 105.0256 | J19: ='Asset Schedule'!J36 -> 116.83767 | K19: ='Asset Schedule'!K36 -> 128.70815 | L19: ='Asset Schedule'!L36 -> 139.64126 | M19: ='Asset Schedule'!M36 -> 149.35234 | P19: 26.46 | Q19: 27.49 | R19: 29.34 | S19: 31.99
A20: EBIT | E20: =E17-E19 -> 146.34 | F20: =F17-F19 -> 180.96 | G20: =G17-G19 -> 259.27 | H20: =H17-H19 -> 297.54 | I20: =I17-I19 -> 411.16287 | J20: =J17-J19 -> 509.08082 | K20: =K17-K19 -> 614.46658 | L20: =L17-L19 -> 736.8903 | M20: =M17-M19 -> 899.36891 | P20: =P17-P19 -> 67.19 | Q20: =Q17-Q19 -> 65.11 | R20: =R17-R19 -> 70.87 | S20: =S17-S19 -> 94.37
A21: EBIT Margin | E21: =E20/E8 -> 0.031463187 | F21: =F20/F8 -> 0.036357061 | G21: =G20/G8 -> 0.054647585 | H21: =H20/H8 -> 0.054445246 | I21: =I20/I8 -> 0.064074675 | J21: =J20/J8 -> 0.067832913 | K21: =K20/K8 -> 0.072225768 | L21: =L20/L8 -> 0.076042073 | M21: =M20/M8 -> 0.081091098
B23: Interest expense | E23: 102.87 | F23: 122.5 | G23: 121.56 | H23: =SUM(P23:S23) -> 119.76 | I23: ='Debt Schedule'!I32 -> 72.520786 | J23: ='Debt Schedule'!J32 -> 69.810572 | K23: ='Debt Schedule'!K32 -> 69.921855 | L23: ='Debt Schedule'!L32 -> 72.008551 | M23: ='Debt Schedule'!M32 -> 75.038775 | P23: 30.73 | Q23: 29.58 | R23: 30.36 | S23: 29.09
B24: Other income | E24: 25.77 | F24: 16.39 | G24: 11.19 | H24: =SUM(P24:S24) -> 22.78 | I24: 20 | J24: 22 | K24: 24 | L24: 25 | M24: 26 | P24: 3.11 | Q24: 4.56 | R24: 6.36 | S24: 8.75
A25: PBT | E25: =E20-E23+E24 -> 69.24 | F25: =F20-F23+F24 -> 74.85 | G25: =G20-G23+G24 -> 148.9 | H25: =H20-H23+H24 -> 200.56 | I25: =I20-I23+I24 -> 358.64208 | J25: =J20-J23+J24 -> 461.27025 | K25: =K20-K23+K24 -> 568.54473 | L25: =L20-L23+L24 -> 689.88175 | M25: =M20-M23+M24 -> 850.33013 | P25: =P20-P23+P24 -> 39.57 | Q25: =Q20-Q23+Q24 -> 40.09 | R25: =R20-R23+R24 -> 46.87 | S25: =S20-S23+S24 -> 74.03
B26: Taxes | E26: 15.09 | F26: 15.95 | G26: 36.71 | H26: =SUM(P26:S26) -> 51.05 | I26: =I25*Assumptions!I37 -> 90.270212 | J26: =J25*Assumptions!J37 -> 116.10172 | K26: =K25*Assumptions!K37 -> 143.10271 | L26: =L25*Assumptions!L37 -> 173.64324 | M26: =M25*Assumptions!M37 -> 214.02809 | P26: 10.37 | Q26: 10.52 | R26: 11.64 | S26: 18.52
A27: PAT | E27: =E25-E26 -> 54.15 | F27: =F25-F26 -> 58.9 | G27: =G25-G26 -> 112.19 | H27: =H25-H26 -> 149.51 | I27: =I25-I26 -> 268.37187 | J27: =J25-J26 -> 345.16853 | K27: =K25-K26 -> 425.44202 | L27: =L25-L26 -> 516.23851 | M27: =M25-M26 -> 636.30204 | P27: =P25-P26 -> 29.2 | Q27: =Q25-Q26 -> 29.57 | R27: =R25-R26 -> 35.23 | S27: =S25-S26 -> 55.51
A30: Operating Metrics
A31: Sales Volume Sold (Unit) | C31: thousands | E31: 12979.776 | F31: 14468.911 | G31: 13363.934 | H31: 14609.531 | I31: <<Aprox)
A32: EBITDA per unit | C32: ₹/unit | E32: =E17*1000/E31 -> 16.83234 | F32: =F17*1000/F31 -> 18.37526 | G32: =G17*1000/G31 -> 26.376214 | H32: =H17*1000/H31 -> 28.256896
A33: Growth | C33: % | F33: =F32/E32-1 -> 0.091664019 | G33: =G32/F32-1 -> 0.43541997 | H33: =H32/G32-1 -> 0.071302166
A34: HR Coil (Hot Rolled Steel) Steel price | C34: ₹/MT | E34: 67000 | F34: 62000 | G34: 61000 | H34: 64000 | I34: << Major cost
A35: Growth | C35: % | F35: =F34/E34-1 -> -0.074626866 | G35: =G34/F34-1 -> -0.016129032 | H35: =H34/G34-1 -> 0.049180328
A36: Volume HR Coil Steel used | C36: MT | E36: 389393.28 | F36: 434067.34 | G36: 400918.03 | H36: 438285.94
A37: Power & Fuel / Electricity cost | C37: ₹ Cr | E37: =0.3*E14 -> 168.537 | F37: =0.3*F14 -> 177.132 | G37: =0.3*G14 -> 172.035 | H37: =0.3*H14 -> 217.599
A42: Horizontal Analysis (YoY % change) | F42: =F2 -> 45382 | G42: =G2 -> 45747 | H42: =H2 -> 46112
B44: Revenue Growth | D44: % | F44: =F8/E8-1 -> 0.070122443 | G44: =G8/F8-1 -> -0.046792438 | H44: =H8/G8-1 -> 0.15187168
B45: Raw Material Cost | D45: % | F45: =F11/E11-1 -> 0.031538731 | G45: =G11/F11-1 -> -0.091266313 | H45: =H11/G11-1 -> 0.14697007
B46: =B13 -> Employee benefit expense | D46: % | F46: =F13/E13-1 -> 0.15045974 | G46: =G13/F13-1 -> -0.01155968 | H46: =H13/G13-1 -> 0.16566087
B47: =B14 -> Other Expenses | D47: % | F47: =F14/E14-1 -> 0.050997704 | G47: =G14/F14-1 -> -0.028775151 | H47: =H14/G14-1 -> 0.26485308
B48: =A17 -> EBITDA | D48: % | F48: =F17/E17-1 -> 0.21690773 | G48: =G17/F17-1 -> 0.32579832 | H48: =H17/G17-1 -> 0.17115379
B50: =B19 -> Depreciation | D50: % | F50: =F19/E19-1 -> 0.17701691 | G50: =G19/F19-1 -> 0.097868331 | H50: =H19/G19-1 -> 0.2366445
B51: =B23 -> Interest expense | D51: % | F51: =F23/E23-1 -> 0.19082337 | G51: =G23/F23-1 -> -0.0076734694 | H51: =H23/G23-1 -> -0.014807502
B52: =A27 -> PAT | D52: % | F52: =F27/E27-1 -> 0.087719298 | G52: =G27/F27-1 -> 0.90475382 | H52: =H27/G27-1 -> 0.33264997
A56: Vertical Analysis (% of total revenue) | E56: =E2 -> 45016 | F56: =F2 -> 45382 | G56: =G2 -> 45747 | H56: =H2 -> 46112
...

Sheet BS
A2: =IS!A2 -> (Unless Otherwise specified, all financials are in ₹ Cr) | E2: =IS!E2 -> 45016 | F2: =IS!F2 -> 45382 | G2: =IS!G2 -> 45747 | H2: =IS!H2 -> 46112 | I2: =IS!I2 -> 46477 | J2: =IS!J2 -> 46843 | K2: =IS!K2 -> 47208 | L2: =IS!L2 -> 47573 | M2: =IS!M2 -> 47938 | Q2: =E2 -> 45016 | R2: =F2 -> 45382 | S2: =G2 -> 45747 | T2: =H2 -> 46112
A3: Uses of Funds
A5: Assets
A7: Current Assets
B8: Cash & Cash-Equivalents | E8: 4.04 | F8: 4.76 | G8: 4.2 | H8: 3.64 | I8: =CF!I43 -> 61.943191 | J8: =CF!J43 -> 214.0332 | K8: =CF!K43 -> 496.30357 | L8: =CF!L43 -> 862.21927 | M8: =CF!M43 -> 1325.2113
B9: Short-Term Securities | E9: 0.6 | F9: 0.54 | G9: 0.71 | H9: 0.52 | I9: =AVERAGE(E9:H9) -> 0.5925 | J9: =AVERAGE(F9:I9) -> 0.590625 | K9: =AVERAGE(G9:J9) -> 0.60328125 | L9: =AVERAGE(H9:K9) -> 0.57660156 | M9: =AVERAGE(I9:L9) -> 0.59075195
B10: Accounts Receivable | E10: 829.12 | F10: 726.34 | G10: 800.82 | H10: 817.69 | I10: =Assumptions!I46*Assumptions!I11/365 -> 966.93504 | J10: =Assumptions!J46*Assumptions!J11/365 -> 1151.4403 | K10: =Assumptions!K46*Assumptions!K11/365 -> 1258.6559 | L10: =Assumptions!L46*Assumptions!L11/365 -> 1513.3204 | M10: =Assumptions!M46*Assumptions!M11/365 -> 1823.1528
B11: Inventory | E11: 844.27 | F11: 882.5 | G11: 769.03 | H11: 746.43 | I11: =Assumptions!I47*Assumptions!I44/365 -> 889.15322 | J11: =Assumptions!J47*Assumptions!J44/365 -> 1017.7158 | K11: =Assumptions!K47*Assumptions!K44/365 -> 1212.5238 | L11: =Assumptions!L47*Assumptions!L44/365 -> 1328.1413 | M11: =Assumptions!M47*Assumptions!M44/365 -> 1540.7096
B12: Other Current Assets | E12: 157.39 | F12: 173.57 | G12: 171.34 | H12: 236 | I12: =Assumptions!I49*Assumptions!I11 -> 256.6773 | J12: =Assumptions!J49*Assumptions!J11 -> 285.18709 | K12: =Assumptions!K49*Assumptions!K11 -> 306.27292 | L12: =Assumptions!L49*Assumptions!L11 -> 339.16961 | M12: =Assumptions!M49*Assumptions!M11 -> 377.08878
B13: Total Current Assets | E13: =SUM(E8:E12) -> 1835.42 | F13: =SUM(F8:F12) -> 1787.71 | G13: =SUM(G8:G12) -> 1746.1 | H13: =SUM(H8:H12) -> 1804.28 | I13: =SUM(I8:I12) -> 2175.3013 | J13: =SUM(J8:J12) -> 2668.967 | K13: =SUM(K8:K12) -> 3274.3594 | L13: =SUM(L8:L12) -> 4043.4272 | M13: =SUM(M8:M12) -> 5066.7533
A15: Non Current Assets
B16: Long-Term Securities | E16: 27.89 | F16: 32.07 | G16: 46.27 | H16: 78.34 | I16: =H16-CF!I25-CF!I27 -> 68.2575 | J16: =I16-CF!J25-CF!J27 -> 58.654375 | K16: =J16-CF!K25-CF!K27 -> 49.192969 | L16: =K16-CF!L25-CF!L27 -> 39.583711 | M16: =L16-CF!M25-CF!M27 -> 26.644639
B17: Property, Plant & Equipment | E17: 1111.56 | F17: 1191.29 | G17: 1310.53 | H17: 1538.05 | I17: =H17-CF!I7-CF!I9-CF!I26-CF!I24 -> 1659.1411 | J17: =I17-CF!J7-CF!J9-CF!J26-CF!J24 -> 1766.4916 | K17: =J17-CF!K7-CF!K9-CF!K26-CF!K24 -> 1863.0395 | L17: =K17-CF!L7-CF!L9-CF!L26-CF!L24 -> 1923.0501 | M17: =L17-CF!M7-CF!M9-CF!M26-CF!M24 -> 1939.9569
B18: Goodwill | E18: 0 | F18: 31.8 | G18: 31.8 | H18: 31.8 | I18: =H18 -> 31.8 | J18: =I18 -> 31.8 | K18: =J18 -> 31.8 | L18: =K18 -> 31.8 | M18: =L18 -> 31.8
B19: Other Intangible Assets | E19: 2.52 | F19: 3.81 | G19: 3.29 | H19: 4.98 | I19: =H19 -> 4.98 | J19: =I19 -> 4.98 | K19: =J19 -> 4.98 | L19: =K19 -> 4.98 | M19: =L19 -> 4.98
B20: Deffered Tax Assets | E20: 0 | F20: 0 | G20: 0 | H20: 12.76 | I20: =H20-CF!I8 -> 12.76 | J20: =I20-CF!J8 -> 12.76 | K20: =J20-CF!K8 -> 12.76 | L20: =K20-CF!L8 -> 12.76 | M20: =L20-CF!M8 -> 12.76
B21: Other Assets | E21: 32.16 | F21: 57.46 | G21: 50.41 | H21: 56.72 | I21: =Assumptions!I58*Assumptions!I11 -> 57.752393 | J21: =Assumptions!J58*Assumptions!J11 -> 67.544311 | K21: =Assumptions!K58*Assumptions!K11 -> 76.568231 | L21: =Assumptions!L58*Assumptions!L11 -> 87.215044 | M21: =Assumptions!M58*Assumptions!M11 -> 99.817617
B22: Total Non Current Assets | E22: =SUM(E16:E21) -> 1174.13 | F22: =SUM(F16:F21) -> 1316.43 | G22: =SUM(G16:G21) -> 1442.3 | H22: =SUM(H16:H21) -> 1722.65 | I22: =SUM(I16:I21) -> 1834.691 | J22: =SUM(J16:J21) -> 1942.2303 | K22: =SUM(K16:K21) -> 2038.3407 | L22: =SUM(L16:L21) -> 2099.3888 | M22: =SUM(M16:M21) -> 2115.9592
A24: Total Assets | E24: =E13+E22 -> 3009.55 | F24: =F13+F22 -> 3104.14 | G24: =G13+G22 -> 3188.4 | H24: =H13+H22 -> 3526.93 | I24: =I13+I22 -> 4009.9923 | J24: =J13+J22 -> 4611.1973 | K24: =K13+K22 -> 5312.7001 | L24: =L13+L22 -> 6142.816 | M24: =M13+M22 -> 7182.7124
A26: Sources of Funds
A28: Liabilities
A30: Current Liabilities
B31: Short-term Debt | E31: 571.08 | F31: 479.44 | G31: 428.9 | H31: 454.36 | I31: =H31+CF!I33 -> 444.31546 | J31: =I31+CF!J33 -> 435.88506 | K31: =J31+CF!K33 -> 479.15232 | L31: =K31+CF!L33 -> 519.31561 | M31: =L31+CF!M33 -> 588.3014
B32: Accounts Payable | E32: 1164.57 | F32: 1197.07 | G32: 1221.29 | H32: 1338.18 | I32: =Assumptions!I48*Assumptions!I44/365 -> 1568.1429 | J32: =Assumptions!J48*Assumptions!J44/365 -> 1828.1191 | K32: =Assumptions!K48*Assumptions!K44/365 -> 2063.4176 | L32: =Assumptions!L48*Assumptions!L44/365 -> 2342.3584 | M32: =Assumptions!M48*Assumptions!M44/365 -> 2668.7291
B33: Other Current Liabilities | E33: 229.19 | F33: 221.71 | G33: 229.81 | H33: 270.79 | I33: =Assumptions!I81*Assumptions!I11 -> 320.84663 | J33: =Assumptions!J81*Assumptions!J11 -> 375.24617 | K33: =Assumptions!K81*Assumptions!K11 -> 425.37906 | L33: =Assumptions!L81*Assumptions!L11 -> 484.52802 | M33: =Assumptions!M81*Assumptions!M11 -> 554.54232
B34: Total Current Liabilities | E34: =SUM(E31:E33) -> 1964.84 | F34: =SUM(F31:F33) -> 1898.22 | G34: =SUM(G31:G33) -> 1880 | H34: =SUM(H31:H33) -> 2063.33 | I34: =SUM(I31:I33) -> 2333.305 | J34: =SUM(J31:J33) -> 2639.2504 | K34: =SUM(K31:K33) -> 2967.949 | L34: =SUM(L31:L33) -> 3346.202 | M34: =SUM(M31:M33) -> 3811.5729
A36: Non Current Liabilities
B37: Long-term lease liabilities | E37: 11 | F37: 10.78 | G37: 4.88 | H37: 56.47 | I37: =H37+CF!I32 -> 37.47 | J37: =I37+CF!J32 -> 18.47 | K37: =J37+CF!K32 -> -0.53 | L37: =K37+CF!L32 -> -9.1917337 | M37: =L37+CF!M32 -> -9.1917337
B38: Long-term debt | E38: 203.25 | F38: 287.55 | G38: 302.98 | H38: 257.29 | I38: =H38+CF!I34 -> 248.645 | J38: =I38+CF!J34 -> 241.82307 | K38: =J38+CF!K34 -> 239.17488 | L38: =K38+CF!L34 -> 225.84165 | M38: =L38+CF!M34 -> 203.70773
B39: Other long-term liabilities | E39: 53.29 | F39: 58.68 | G39: 68.13 | H39: 94.91 | I39: =Assumptions!I82*Assumptions!I11 -> 115.50479 | J39: =Assumptions!J82*Assumptions!J11 -> 150.09847 | K39: =Assumptions!K82*Assumptions!K11 -> 187.16679 | L39: =Assumptions!L82*Assumptions!L11 -> 232.57345 | M39: =Assumptions!M82*Assumptions!M11 -> 288.36201
B40: Total Non Current Liabilities | E40: =SUM(E37:E39) -> 267.54 | F40: =SUM(F37:F39) -> 357.01 | G40: =SUM(G37:G39) -> 375.99 | H40: =SUM(H37:H39) -> 408.67 | I40: =SUM(I37:I39) -> 401.61979 | J40: =SUM(J37:J39) -> 410.39154 | K40: =SUM(K37:K39) -> 425.81166 | L40: =SUM(L37:L39) -> 449.22336 | M40: =SUM(M37:M39) -> 482.878
A42: Shareholders' Equity
B43: Common Stock | E43: 24.06 | F43: 24.43 | G43: 24.43 | H43: 24.43 | I43: =H43 -> 24.43 | J43: =I43 -> 24.43 | K43: =J43 -> 24.43 | L43: =K43 -> 24.43 | M43: =L43 -> 24.43
B44: Retained Earnings (incl. Treasury Stock) | E44: 753.11 | F44: 824.48 | G44: 907.98 | H44: 1030.5 | I44: =H44+IS!I27+CF!I31 -> 1250.5649 | J44: =I44+IS!J27+CF!J31 -> 1537.0548 | K44: =J44+IS!K27+CF!K31 -> 1894.4261 | L44: =K44+IS!L27+CF!L31 -> 2322.9041 | M44: =L44+IS!M27+CF!M31 -> 2863.7608
B45: Total Shareholder's Equity | E45: =SUM(E43:E44) -> 777.17 | F45: =SUM(F43:F44) -> 848.91 | G45: =SUM(G43:G44) -> 932.41 | H45: =SUM(H43:H44) -> 1054.93 | I45: =SUM(I43:I44) -> 1274.9949 | J45: =SUM(J43:J44) -> 1561.4848 | K45: =SUM(K43:K44) -> 1918.8561 | L45: =SUM(L43:L44) -> 2347.3341 | M45: =SUM(M43:M44) -> 2888.1908
A47: Total Liabilities & Shareholder's Equity | E47: =E34+E40+E45 -> 3009.55 | F47: =F34+F40+F45 -> 3104.14 | G47: =G34+G40+G45 -> 3188.4 | H47: =H34+H40+H45 -> 3526.93 | I47: =I34+I40+I45 -> 4009.9198 | J47: =J34+J40+J45 -> 4611.1267 | K47: =K34+K40+K45 -> 5312.6168 | L47: =L34+L40+L45 -> 6142.7594 | M47: =M34+M40+M45 -> 7182.6417
B49: Balance Check | E49: =(ROUND(E24,0)-ROUND(E47,0)) -> 0 | F49: =(ROUND(F24,0)-ROUND(F47,0)) -> 0 | G49: =(ROUND(G24,0)-ROUND(G47,0)) -> 0 | H49: =(ROUND(H24,0)-ROUND(H47,0)) -> 0 | I49: =(ROUND(I24,0)-ROUND(I47,0)) -> 0 | J49: =(ROUND(J24,0)-ROUND(J47,0)) -> 0 | K49: =(ROUND(K24,0)-ROUND(K47,0)) -> 0 | L49: =(ROUND(L24,0)-ROUND(L47,0)) -> 0 | M49: =(ROUND(M24,0)-ROUND(M47,0)) -> 0

Sheet CF
A2: =IS!A2 -> (Unless Otherwise specified, all financials are in ₹ Cr) | E2: =IS!E2 -> 45016 | F2: =IS!F2 -> 45382 | G2: =IS!G2 -> 45747 | H2: =IS!H2 -> 46112 | I2: =IS!I2 -> 46477 | J2: =IS!J2 -> 46843 | K2: =IS!K2 -> 47208 | L2: =IS!L2 -> 47573 | M2: =IS!M2 -> 47938
A4: Cashflow from Operating Activities
B6: PAT | E6: 53.67 | F6: 61.16 | G6: 112.56 | H6: 152.63 | I6: =IS!I27 -> 268.37187 | J6: =IS!J27 -> 345.16853 | K6: =IS!K27 -> 425.44202 | L6: =IS!L27 -> 516.23851 | M6: =IS!M27 -> 636.30204
B7: Add: Depreciation | E7: 72.14 | F7: 84.91 | G7: 93.22 | H7: 115.28 | I7: =IS!I19 -> 105.0256 | J7: =IS!J19 -> 116.83767 | K7: =IS!K19 -> 128.70815 | L7: =IS!L19 -> 139.64126 | M7: =IS!M19 -> 149.35234
B8: Deferred tax adjustments | E8: 15.14 | F8: 16.68 | G8: 36.85 | H8: 49.28 | I8: 0 | J8: 0 | K8: 0 | L8: 0 | M8: 0
B9: Interest Expenses & Loss on PPE | E9: 93.8 | F9: 140.42 | G9: 123.66 | H9: 144.89 | I9: =IS!I23 -> 72.520786 | J9: =IS!J23 -> 69.810572 | K9: =IS!K23 -> 69.921855 | L9: =IS!L23 -> 72.008551 | M9: =IS!M23 -> 75.038775
B11: Net Change in Working Capital
B12: Less: Increase in Trade Receivables | E12: 79.24 | F12: 21.06 | G12: -59.53 | H12: 18.14 | I12: =BS!H10-BS!I10 -> -149.24504 | J12: =BS!I10-BS!J10 -> -184.50527 | K12: =BS!J10-BS!K10 -> -107.21554 | L12: =BS!K10-BS!L10 -> -254.66454 | M12: =BS!L10-BS!M10 -> -309.83244
B13: Less: Increase in Inventory | E13: -44.85 | F13: -0.17 | G13: 110.5 | H13: -5.07 | I13: =BS!H11-BS!I11 -> -142.72322 | J13: =BS!I11-BS!J11 -> -128.56259 | K13: =BS!J11-BS!K11 -> -194.80795 | L13: =BS!K11-BS!L11 -> -115.61758 | M13: =BS!L11-BS!M11 -> -212.56828
B14: Less: Other Current Assets | E14: 28.35 | F14: 3.42 | G14: -18.5 | H14: -37.08 | I14: =BS!H12-BS!I12 -> -20.677302 | J14: =BS!I12-BS!J12 -> -28.50979 | K14: =BS!J12-BS!K12 -> -21.085833 | L14: =BS!K12-BS!L12 -> -32.89669 | M14: =BS!L12-BS!M12 -> -37.919163
B15: Less: Other Non current Assets | E15: 0 | F15: 0 | G15: 0 | H15: 0 | I15: =BS!H21-BS!I21 -> -1.0323929 | J15: =BS!I21-BS!J21 -> -9.7919182 | K15: =BS!J21-BS!K21 -> -9.02392 | L15: =BS!K21-BS!L21 -> -10.646813 | M15: =BS!L21-BS!M21 -> -12.602574
B16: Add: Increase in Trade payable | E16: 67.3 | F16: 32.5 | G16: 8.45 | H16: 73.34 | I16: =BS!I32-BS!H32 -> 229.96295 | J16: =BS!J32-BS!I32 -> 259.97618 | K16: =BS!K32-BS!J32 -> 235.29849 | L16: =BS!L32-BS!K32 -> 278.94073 | M16: =BS!M32-BS!L32 -> 326.37079
B17: Add: Other operating adjustments | E17: 7.86 | F17: -30.64 | G17: -6.74 | H17: -34.05 | I17: =BS!I33+BS!I39-BS!H33-BS!H39 -> 70.651413 | J17: =BS!J33+BS!J39-BS!I33-BS!I39 -> 88.993229 | K17: =BS!K33+BS!K39-BS!J33-BS!J39 -> 87.201207 | L17: =BS!L33+BS!L39-BS!K33-BS!K39 -> 104.55562 | M17: =BS!M33+BS!M39-BS!L33-BS!L39 -> 125.80286
B18: Net Change in Working Capital | E18: =SUM(E12:E17) -> 137.9 | F18: =SUM(F12:F17) -> 26.17 | G18: =SUM(G12:G17) -> 34.18 | H18: =SUM(H12:H17) -> 15.28 | I18: =SUM(I12:I17) -> -13.063593 | J18: =SUM(J12:J17) -> -2.400154 | K18: =SUM(K12:K17) -> -9.6335497 | L18: =SUM(L12:L17) -> -30.329265 | M18: =SUM(M12:M17) -> -120.7488
B20: Cash Flow from Operations | E20: =SUM(E6:E9,E12:E17) -> 372.65 | F20: =SUM(F6:F9,F12:F17) -> 329.34 | G20: =SUM(G6:G9,G12:G17) -> 400.47 | H20: =SUM(H6:H9,H12:H17) -> 477.36 | I20: =SUM(I6:I9,I12:I17) -> 432.85466 | J20: =SUM(J6:J9,J12:J17) -> 529.41662 | K20: =SUM(K6:K9,K12:K17) -> 614.43847 | L20: =SUM(L6:L9,L12:L17) -> 697.55906 | M20: =SUM(M6:M9,M12:M17) -> 739.94436
A22: Cashflow from Investment Activities
B23: Purchase of Securities | E23: 0 | F23: 0 | G23: 0 | H23: 0
B24: Proceeds from Maturities & Sales | E24: 1.6 | F24: 0.18 | G24: 1.25 | H24: 2.42 | I24: ='Asset Schedule'!I6 -> 1.3625 | J24: ='Asset Schedule'!J6 -> 1.303125 | K24: ='Asset Schedule'!K6 -> 1.5839062 | L24: ='Asset Schedule'!L6 -> 1.6673828 | M24: ='Asset Schedule'!M6 -> 1.4792285
B25: Purchase of Long-Term Investments | E25: 0 | F25: -3.83 | G25: -11.13 | H25: -24.71 | I25: =AVERAGE(E25:H25) -> -9.9175 | J25: =AVERAGE(F25:I25) -> -12.396875 | K25: =AVERAGE(G25:J25) -> -14.538594 | L25: =AVERAGE(H25:K25) -> -15.390742 | M25: =AVERAGE(I25:L25) -> -13.060928
B26: Capital Expenditure | E26: -151.27 | F26: -150.28 | G26: -209.26 | H26: -276.78 | I26: =-'Asset Schedule'!I9 -> -300 | J26: =-'Asset Schedule'!J9 -> -295.30187 | K26: =-'Asset Schedule'!K9 -> -296.76176 | L26: =-'Asset Schedule'!L9 -> -273.32777 | M26: =-'Asset Schedule'!M9 -> -242.7772
B27: Other | E27: 2.1 | F27: 4.2 | G27: 5.91 | H27: 7.37 | I27: =IS!I24 -> 20 | J27: =IS!J24 -> 22 | K27: =IS!K24 -> 24 | L27: =IS!L24 -> 25 | M27: =IS!M24 -> 26
B28: Cashflow from Investment Activities | E28: =SUM(E23:E27) -> -147.57 | F28: =SUM(F23:F27) -> -149.73 | G28: =SUM(G23:G27) -> -213.23 | H28: =SUM(H23:H27) -> -291.7 | I28: =SUM(I23:I27) -> -288.555 | J28: =SUM(J23:J27) -> -284.39562 | K28: =SUM(K23:K27) -> -285.71645 | L28: =SUM(L23:L27) -> -262.05113 | M28: =SUM(M23:M27) -> -228.3589
A30: Cashflow from Financing Activities
B31: Dividend Issued | E31: -27.14 | F31: -9.59 | G31: -28.95 | H31: -30.06 | I31: =-IS!I27*Assumptions!I83 -> -48.306937 | J31: =-IS!J27*Assumptions!J83 -> -58.678649 | K31: =-IS!K27*Assumptions!K83 -> -68.070723 | L31: =-IS!L27*Assumptions!L83 -> -87.760547 | M31: =-IS!M27*Assumptions!M83 -> -95.445306
B32: Repayment of Lease Liabilities | E32: -9.09 | F32: -10.19 | G32: -10.97 | H32: -18.73 | I32: =-Assumptions!I77 -> -19 | J32: =-Assumptions!J77 -> -19 | K32: =-Assumptions!K77 -> -19 | L32: =-Assumptions!L77 -> -8.6617337 | M32: =-Assumptions!M77 -> 0
B33: Increase/(Decrease) in Working Capital Borrowings | E33: -25.11 | F33: 11.53 | G33: -115.73 | H33: 19.06 | I33: =Assumptions!I67 -> -10.044535 | J33: =Assumptions!J67 -> -8.430407 | K33: =Assumptions!K67 -> 43.267262 | L33: =Assumptions!L67 -> 40.163286 | M33: =Assumptions!M67 -> 68.985791
B34: Proceeds/(Repayment) Long-Term Debt | E34: -45.65 | F34: -17.48 | G34: 81.36 | H34: -26.95 | I34: =Assumptions!I68+Assumptions!I73 -> -8.645 | J34: =Assumptions!J68+Assumptions!J73 -> -6.821925 | K34: =Assumptions!K68+Assumptions!K73 -> -2.648199 | L34: =Assumptions!L68+Assumptions!L73 -> -13.333229 | M34: =Assumptions!M68+Assumptions!M73 -> -22.133918
B35: Interest Expense | E35: -103.78 | F35: -120.3 | G35: -113.24 | H35: -118.08 | I35: =-IS!I23 -> -72.520786 | J35: =-IS!J23 -> -69.810572 | K35: =-IS!K23 -> -69.921855 | L35: =-IS!L23 -> -72.008551 | M35: =-IS!M23 -> -75.038775
B36: Cashflow from Financing Activities | E36: =SUM(E31:E35) -> -210.77 | F36: =SUM(F31:F35) -> -146.03 | G36: =SUM(G31:G35) -> -187.53 | H36: =SUM(H31:H35) -> -174.76 | I36: =SUM(I31:I34) -> -85.996472 | J36: =SUM(J31:J34) -> -92.930981 | K36: =SUM(K31:K34) -> -46.451661 | L36: =SUM(L31:L34) -> -69.592224 | M36: =SUM(M31:M34) -> -48.593433
B38: Net Cashflow | E38: =E20+E28+E36 -> 14.31 | F38: =F20+F28+F36 -> 33.58 | G38: =G20+G28+G36 -> -0.29 | H38: =H20+H28+H36 -> 10.9 | I38: =I20+I28+I36 -> 58.303191 | J38: =J20+J28+J36 -> 152.09001 | K38: =K20+K28+K36 -> 282.27036 | L38: =L20+L28+L36 -> 365.9157 | M38: =M20+M28+M36 -> 462.99202
A40: Cash Balance
B41: Beginning Year Cash | I41: =H43 -> 3.64 | J41: =I43 -> 61.943191 | K41: =J43 -> 214.0332 | L41: =K43 -> 496.30357 | M41: =L43 -> 862.21927
B42: Increase/Decrease in Cash | I42: =I38 -> 58.303191 | J42: =J38 -> 152.09001 | K42: =K38 -> 282.27036 | L42: =L38 -> 365.9157 | M42: =M38 -> 462.99202
B43: Cash & Cash Equivalents | H43: =BS!H8 -> 3.64 | I43: =SUM(I41:I42) -> 61.943191 | J43: =SUM(J41:J42) -> 214.0332 | K43: =SUM(K41:K42) -> 496.30357 | L43: =SUM(L41:L42) -> 862.21927 | M43: =SUM(M41:M42) -> 1325.2113
B45: SUPPLEMENTAL DATA:
B46: Cash flow before debt paydown | H46: =SUM(H20,H28,H31:H31) -> 155.6 | I46: =SUM(I20,I28,I31:I31) -> 95.992726 | J46: =SUM(J20,J28,J31:J31) -> 186.34234 | K46: =SUM(K20,K28,K31:K31) -> 260.6513 | L46: =SUM(L20,L28,L31:L31) -> 347.74738 | M46: =SUM(M20,M28,M31:M31) -> 416.14015

Sheet Valuation
A2: =IS!A2 -> (Unless Otherwise specified, all financials are in ₹ Cr) | E2: =IS!E2 -> 45016 | F2: =IS!F2 -> 45382 | G2: =IS!G2 -> 45747 | H2: =IS!H2 -> 46112 | I2: =IS!I2 -> 46477 | J2: =IS!J2 -> 46843 | K2: =IS!K2 -> 47208 | L2: =IS!L2 -> 47573 | M2: =IS!M2 -> 47938
A4: DCF Valuation using FCFF
B6: EBIT | I6: =IS!I20 -> 411.16287 | J6: =IS!J20 -> 509.08082 | K6: =IS!K20 -> 614.46658 | L6: =IS!L20 -> 736.8903 | M6: =IS!M20 -> 899.36891
B7: Tax Rate (%) | D7: =Assumptions!I37 -> 0.2517
B8: EBIT*(1-t) | I8: =I6*(1-$D$7) -> 307.67317 | J8: =J6*(1-$D$7) -> 380.94518 | K8: =K6*(1-$D$7) -> 459.80535 | L8: =L6*(1-$D$7) -> 551.41501 | M8: =M6*(1-$D$7) -> 672.99775
B9: Add: Depreciation | I9: =IS!I19 -> 105.0256 | J9: =IS!J19 -> 116.83767 | K9: =IS!K19 -> 128.70815 | L9: =IS!L19 -> 139.64126 | M9: =IS!M19 -> 149.35234
B10: Less: Increase in Working Capital | I10: =CF!I18 -> -13.063593 | J10: =CF!J18 -> -2.400154 | K10: =CF!K18 -> -9.6335497 | L10: =CF!L18 -> -30.329265 | M10: =CF!M18 -> -120.7488
B11: Less: Capex and increase in WIP | I11: =CF!I26 -> -300 | J11: =CF!J26 -> -295.30187 | K11: =CF!K26 -> -296.76176 | L11: =CF!L26 -> -273.32777 | M11: =CF!M26 -> -242.7772
B12: Free Cashflow to the Firm (FCFF) | I12: =SUM(I8:I11) -> 99.635181 | J12: =SUM(J8:J11) -> 200.08082 | K12: =SUM(K8:K11) -> 282.11818 | L12: =SUM(L8:L11) -> 387.39923 | M12: =SUM(M8:M11) -> 458.82409
B14: WACC | D14: =Assumptions!D97 -> 0.14134765
B16: Terminal Growth Rate | D16: =Assumptions!D95 -> 0.05
B18: Terminal Value | M18: =M12*(1+D16)/(D14-D16) -> 5273.976
B20: No. of Years | I20: 1 | J20: 2 | K20: 3 | L20: 4 | M20: 5
B21: Discount Factor | I21: =1/(1+$D$14)^I20 -> 0.87615724 | J21: =1/(1+$D$14)^J20 -> 0.7676515 | K21: =1/(1+$D$14)^K20 -> 0.67258342 | L21: =1/(1+$D$14)^L20 -> 0.58928883 | M21: =1/(1+$D$14)^M20 -> 0.51630967
B23: Present Value of FCFF | I23: =I12*I21 -> 87.296085 | J23: =J12*J21 -> 153.59234 | K23: =K12*K21 -> 189.74801 | L23: =L12*L21 -> 228.29004 | M23: =M12*M21 -> 236.89532
B24: Present Value of Terminal Value | M24: =M18*M21 -> 2723.0049
B26: Enterprise Value | H26: =SUM(I23:M23,M24) -> 3618.8267
B27: Less: Total Debt | H27: =-Assumptions!D85 -> -711.65
B28: Less: Lease Liabilities | H28: =-BS!H37 -> -56.47
B29: Add: Total Cash | H29: =BS!H8 -> 3.64
B30: Less: Any Contingent Liabilities | H30: 0
B31: Add: Value of Non-Operating Investments (LT Securities) | H31: =BS!H16 -> 78.34
B32: Equity Value | H32: =SUM(H26:H31) -> 2932.6867
B33: No. of Shares | E33: 24433012
B34: Share Price (INR) | D34: =H32*10^7/E33 -> 1200.2968
B38: Using Exit Multiple Method
B40: Exit Multiple:
B41: Steel Strips Wheels (SSWL) | D41: 9.57
B42: Wheel India Ltd | D42: 7.43 | E42: <---Current Multiple
B43: Average | D43: =AVERAGE(D41:D42) -> 8.5
B45: Present Value of Terminal Value (Exit Multiple) | M45: =D43*IS!M17*M21 -> 4602.4519
B47: Enterprise Value | H47: =SUM(I23:M23,M45) -> 5498.2737
B48: Less: Total Debt | H48: =H27 -> -711.65
B49: Less: Lease Liabilities | H49: =H28 -> -56.47
B50: Add: Total Cash | H50: =H29 -> 3.64
B51: Less: Any Contingent Liabilities | H51: =H30 -> 0
B52: Add: Value of Non-Operating Investments (LT Securities) | H52: =H31 -> 78.34
B53: Equity Value | H53: =SUM(H47:H52) -> 4812.1337
B54: No. of Shares | E54: 24433012
B55: Share Price (INR) | D55: =H53*10^7/E54 -> 1969.5213
...

Sheet Ratios
N1: .
A2: =IS!A2 -> (Unless Otherwise specified, all financials are in ₹ Cr) | D2: Status | E2: =IS!E2 -> 45016 | F2: =IS!F2 -> 45382 | G2: =IS!G2 -> 45747 | H2: =IS!H2 -> 46112 | I2: =IS!I2 -> 46477 | J2: =IS!J2 -> 46843 | K2: =IS!K2 -> 47208 | L2: =IS!L2 -> 47573 | M2: =IS!M2 -> 47938 | N2: . | O2: =E2 -> 45016 | P2: =F2 -> 45382 | Q2: =G2 -> 45747 | R2: =H2 -> 46112
N3: .
B4: NOPAT | E4: =IS!E20*(1-Assumptions!E37) -> 114.44701 | F4: =IS!F20*(1-Assumptions!F37) -> 142.39872 | G4: =IS!G20*(1-Assumptions!G37) -> 195.34924 | H4: =IS!H20*(1-Assumptions!H37) -> 221.80497 | I4: =IS!I20*(1-Assumptions!I37) -> 307.67317 | J4: =IS!J20*(1-Assumptions!J37) -> 380.94518 | K4: =IS!K20*(1-Assumptions!K37) -> 459.80535 | L4: =IS!L20*(1-Assumptions!L37) -> 551.41501 | M4: =IS!M20*(1-Assumptions!M37) -> 672.99775
B5: Invested Capital | E5: =BS!E45+BS!E38+BS!E37+BS!E31-BS!E8-BS!E9-BS!E16 -> 1529.97 | F5: =BS!F45+BS!F38+BS!F37+BS!F31-BS!F8-BS!F9-BS!F16 -> 1589.31 | G5: =BS!G45+BS!G38+BS!G37+BS!G31-BS!G8-BS!G9-BS!G16 -> 1617.99 | H5: =BS!H45+BS!H38+BS!H37+BS!H31-BS!H8-BS!H9-BS!H16 -> 1740.55 | I5: =BS!I45+BS!I38+BS!I37+BS!I31-BS!I8-BS!I9-BS!I16 -> 1874.6322 | J5: =BS!J45+BS!J38+BS!J37+BS!J31-BS!J8-BS!J9-BS!J16 -> 1984.3847 | K5: =BS!K45+BS!K38+BS!K37+BS!K31-BS!K8-BS!K9-BS!K16 -> 2090.5535 | L5: =BS!L45+BS!L38+BS!L37+BS!L31-BS!L8-BS!L9-BS!L16 -> 2180.92 | M5: =BS!M45+BS!M38+BS!M37+BS!M31-BS!M8-BS!M9-BS!M16 -> 2318.5615
B6: Market Value Equity | C6: 3848
A8: Solvency Ratios
B9: D/E Ratio | E9: =SUM(BS!E31,BS!E37,BS!E38)/BS!E45 -> 1.0104996 | F9: =SUM(BS!F31,BS!F37,BS!F38)/BS!F45 -> 0.91619842 | G9: =SUM(BS!G31,BS!G37,BS!G38)/BS!G45 -> 0.79016742 | H9: =SUM(BS!H31,BS!H37,BS!H38)/BS!H45 -> 0.72812414 | I9: =SUM(BS!I31,BS!I37,BS!I38)/BS!I45 -> 0.57288892 | J9: =SUM(BS!J31,BS!J37,BS!J38)/BS!J45 -> 0.44584368 | K9: =SUM(BS!K31,BS!K37,BS!K38)/BS!K45 -> 0.37407557 | L9: =SUM(BS!L31,BS!L37,BS!L38)/BS!L45 -> 0.3135325 | M9: =SUM(BS!M31,BS!M37,BS!M38)/BS!M45 -> 0.27104075 | N9: .
B10: Net Debt / EBITDA | E10: =SUM(BS!E31,BS!E37,BS!E38,-BS!E8)/IS!E17 -> 3.5760253 | F10: =SUM(BS!F31,BS!F37,BS!F38,-BS!F8)/IS!F17 -> 2.9074736 | G10: =SUM(BS!G31,BS!G37,BS!G38,-BS!G8)/IS!G17 -> 2.0782434 | H10: =SUM(BS!H31,BS!H37,BS!H38,-BS!H8)/IS!H17 -> 1.8518483 | I10: =SUM(BS!I31,BS!I37,BS!I38,-BS!I8)/IS!I17 -> 1.295045 | J10: =SUM(BS!J31,BS!J37,BS!J38,-BS!J8)/IS!J17 -> 0.77029986 | K10: =SUM(BS!K31,BS!K37,BS!K38,-BS!K8)/IS!K17 -> 0.29803709 | L10: =SUM(BS!L31,BS!L37,BS!L38,-BS!L8)/IS!L17 -> -0.14403788 | M10: =SUM(BS!M31,BS!M37,BS!M38,-BS!M8)/IS!M17 -> -0.51719548 | N10: .
B11: Interest Coverage Ratio | E11: =IS!E17/IS!E23 -> 2.1238456 | F11: =IS!F17/IS!F23 -> 2.1703673 | G11: =IS!G17/IS!G23 -> 2.8997203 | H11: =IS!H17/IS!H23 -> 3.4470608 | I11: =IS!I17/IS!I23 -> 7.1178003 | J11: =IS!J17/IS!J23 -> 8.9659556 | K11: =IS!K17/IS!K23 -> 10.628647 | L11: =IS!L17/IS!L23 -> 12.172604 | M11: =IS!M17/IS!M23 -> 13.975725 | N11: .
B12: DSCR | E12: =(IS!E17-CF!E8)/(-Assumptions!E73-CF!E32-CF!E35) -> 0.78111555 | F12: =(IS!F17-CF!F8)/(-Assumptions!F73-CF!F32-CF!F35) -> 0.9374036 | G12: =(IS!G17-CF!G8)/(-Assumptions!G73-CF!G32-CF!G35) -> 1.4666605 | H12: =(IS!H17-CF!H8)/(-Assumptions!H73-CF!H32-CF!H35) -> 1.3422189 | I12: =(IS!I17-CF!I8)/(-Assumptions!I73-CF!I32-CF!I35) -> 2.3445444 | J12: =(IS!J17-CF!J8)/(-Assumptions!J73-CF!J32-CF!J35) -> 2.7748879 | K12: =(IS!K17-CF!K8)/(-Assumptions!K73-CF!K32-CF!K35) -> 3.1757473 | L12: =(IS!L17-CF!L8)/(-Assumptions!L73-CF!L32-CF!L35) -> 3.7120098 | M12: =(IS!M17-CF!M8)/(-Assumptions!M73-CF!M32-CF!M35) -> 4.4984797 | N12: .
N13: .
A14: Liquidity Ratios | N14: .
